Workbook

Sheet Loops
A1: LoopId | B1: Name | C1: Title | D1: Status | E1: NewConcept | F1: DomainQuestion | G1: MockDataNote | H1: NextSuggestion | I1: TraditionId | J1: TraditionName | K1: TraditionCoreConern | L1: CommitHash | M1: CommitShort | N1: CommitDate | O1: CommitMessage | P1: GitTag
A2: loop-01 | B2: =A2 -> loop-01 | C2: Core domain: Study, Treatment, Stratum, CaseCell → SuccessRate falls out | D2: complete | E2: Studies, Treatments, Strata, CaseCells | F2: For each (stratum, treatment) cell in a study, what is the success rate? | G2: Kidney stone study (Charig 1986): 2 strata (small/large), 2 treatments (A/B), 4 cells. CellSuccessRate is the first derived fact. | H2: Ask: for each treatment, what is its pooled (across all strata) success rate? That requires TreatmentSummary — aggregating CaseCells by treatment, ignoring stratum. | I2: tradition-historical | J2: =LOOKUP(I2, ResearchTraditions[TraditionId], ResearchTraditions[Name]) -> #VALUE! | K2: =LOOKUP(I2, ResearchTraditions[TraditionId], ResearchTraditions[CoreConcern]) -> #VALUE! | L2: b96e0fe6e3402d85b16e9772518d9241c64c1b1e | M2: =LEFT(L2, 7) -> b96e0fe | N2: 46200 | O2: loop-05: StratumVariables + IsParadoxExplained — the DAG witnesses its own explanation | P2: sp-loop-milestone-01-loops-01-10
A3: loop-02 | B3: =A3 -> loop-02 | C3: TreatmentSummary: pooled rate per treatment across all strata | D3: complete | E3: TreatmentSummaries | F3: If you ignore stratum entirely, what is each treatment's overall success rate? | G3: Pooled: A=273/350=78%, B=289/350=83%. B looks better — this is the misleading aggregate view. | H3: Ask: for each (stratum, treatment) pair, what is the success rate WITHIN that stratum? That requires StratumSummary — the view that contradicts the pooled view. | I3: tradition-historical | J3: =LOOKUP(I3, ResearchTraditions[TraditionId], ResearchTraditions[Name]) -> #VALUE! | K3: =LOOKUP(I3, ResearchTraditions[TraditionId], ResearchTraditions[CoreConcern]) -> #VALUE! | L3: b96e0fe6e3402d85b16e9772518d9241c64c1b1e | M3: =LEFT(L3, 7) -> b96e0fe | N3: 46200 | O3: loop-05: StratumVariables + IsParadoxExplained — the DAG witnesses its own explanation | P3: sp-loop-milestone-01-loops-01-10
A4: loop-03 | B4: =A4 -> loop-03 | C4: StratumSummary: per-stratum rate per treatment — the true picture | D4: complete | E4: StratumSummaries | F4: Within each stratum, which treatment has the higher success rate? | G4: Small: A=93.1% > B=86.7%. Large: A=73.0% > B=68.8%. A wins in BOTH strata. Contradiction with pooled view is now visible. | H4: Ask: for each treatment pair in a study, does the pooled winner match the per-stratum winner? That requires TreatmentRanking — the node where the paradox either exists or doesn't. | I4: tradition-historical | J4: =LOOKUP(I4, ResearchTraditions[TraditionId], ResearchTraditions[Name]) -> #VALUE! | K4: =LOOKUP(I4, ResearchTraditions[TraditionId], ResearchTraditions[CoreConcern]) -> #VALUE! | L4: b96e0fe6e3402d85b16e9772518d9241c64c1b1e | M4: =LEFT(L4, 7) -> b96e0fe | N4: 46200 | O4: loop-05: StratumVariables + IsParadoxExplained — the DAG witnesses its own explanation | P4: sp-loop-milestone-01-loops-01-10
A5: loop-04 | B5: =A5 -> loop-04 | C5: TreatmentRanking: does the pooled winner = the per-stratum winner? | D5: complete | E5: TreatmentRankings | F5: When pooled and stratified conclusions disagree — which treatment should actually be preferred? | G5: Pooled winner = B. Per-stratum winner = A in every stratum. Simpson's Paradox: IsReversal = true. This is the paradox as a derived fact, not a modeled entity. | H5: Ask: WHY does the paradox occur? The stratifying variable (stone size) affects both treatment assignment AND outcome. Name it as a StratumVariable with a CausalRole field. | I5: tradition-historical | J5: =LOOKUP(I5, ResearchTraditions[TraditionId], ResearchTraditions[Name]) -> #VALUE! | K5: =LOOKUP(I5, ResearchTraditions[TraditionId], ResearchTraditions[CoreConcern]) -> #VALUE! | L5: b96e0fe6e3402d85b16e9772518d9241c64c1b1e | M5: =LEFT(L5, 7) -> b96e0fe | N5: 46200 | O5: loop-05: StratumVariables + IsParadoxExplained — the DAG witnesses its own explanation | P5: sp-loop-milestone-01-loops-01-10
A6: loop-05 | B6: =A6 -> loop-05 | C6: StratumVariable: name the confounding factor, its causal role, and derive IsConfounder + IsParadoxExplained | D6: complete | E6: StratumVariables (one per study); CausalRole field; IsConfounder boolean; IsParadoxExplained on TreatmentRankings | F6: What IS the stratum variable, why does it confound, and does the model witness its own explanation? | G6: kidney-1986: VariableName=stone_size, CausalRole=confounder, AffectsTreatmentAssignment=true, AffectsOutcome=true → IsConfounder=true → IsParadoxExplained=true on TreatmentRankings. | H6: Ask: how large is the allocation imbalance? Derive TreatmentExposureFraction on CaseCells — the fraction of each treatment's cases that land in each stratum. High imbalance = confounding mechanism as a witnessed number. | I6: tradition-dag | J6: =LOOKUP(I6, ResearchTraditions[TraditionId], ResearchTraditions[Name]) -> #VALUE! | K6: =LOOKUP(I6, ResearchTraditions[TraditionId], ResearchTraditions[CoreConcern]) -> #VALUE! | L6: b96e0fe6e3402d85b16e9772518d9241c64c1b1e | M6: =LEFT(L6, 7) -> b96e0fe | N6: 46200 | O6: loop-05: StratumVariables + IsParadoxExplained — the DAG witnesses its own explanation | P6: sp-loop-milestone-01-loops-01-10
A7: loop-06 | B7: =A7 -> loop-06 | C7: TreatmentExposureFraction: the allocation imbalance as a witnessed number | D7: complete | E7: TreatmentExposureFraction field on CaseCells (Cases / TotalCasesForTreatment in this study) | F7: What fraction of each treatment's total cases fall in each stratum? High imbalance across strata is the mechanism of confounding. | G7: A: 263/350=75% in large-stone stratum. B: 80/350=23% in large-stone stratum. The 52-point gap IS the mechanism — now a first-class derived number. | H7: Add a degenerate study where treatment allocation is perfectly balanced across strata. IsReversal must be FALSE — not because the data says so, but because the algebra guarantees it. The model witnesses its own structural impossibility. | I7: tradition-epidemiology | J7: =LOOKUP(I7, ResearchTraditions[TraditionId], ResearchTraditions[Name]) -> #VALUE! | K7: =LOOKUP(I7, ResearchTraditions[TraditionId], ResearchTraditions[CoreConcern]) -> #VALUE! | L7: b96e0fe6e3402d85b16e9772518d9241c64c1b1e | M7: =LEFT(L7, 7) -> b96e0fe | N7: 46200 | O7: loop-05: StratumVariables + IsParadoxExplained — the DAG witnesses its own explanation | P7: sp-loop-milestone-01-loops-01-10
A8: loop-07 | B8: =A8 -> loop-07 | C8: Degenerate study: balanced allocation → IsReversal structurally impossible | D8: complete | E8: Second Studies row (balanced-synthetic); equal TreatmentExposureFraction across strata; IsReversal = FALSE by construction | F8: If every stratum gets the same treatment-allocation fraction, can a reversal occur? The DAG should witness that it cannot. | G8: Synthetic: A and B each assigned 50/50 to small/large strata. A=60% success both strata, B=50% both. Pooled: A=60%, B=50%. No reversal. IsParadoxExplained vacuously true (IsConfounder=false, no confounding, no reversal). | H8: Add Berkeley 1973 — same DAG, contested domain. Aggregate: women admitted at lower rate. Per-department: women admitted at equal or higher rate in most. IsReversal=true. But IsConfounder is ambiguous — department choice may be downstream of gender (mediator, not confounder). The model witnesses its own explanatory limits. | I8: tradition-historical | J8: =LOOKUP(I8, ResearchTraditions[TraditionId], ResearchTraditions[Name]) -> #VALUE! | K8: =LOOKUP(I8, ResearchTraditions[TraditionId], ResearchTraditions[CoreConcern]) -> #VALUE! | L8: b96e0fe6e3402d85b16e9772518d9241c64c1b1e | M8: =LEFT(L8, 7) -> b96e0fe | N8: 46200 | O8: loop-05: StratumVariables + IsParadoxExplained — the DAG witnesses its own explanation | P8: sp-loop-milestone-01-loops-01-10
A9: loop-08 | B9: =A9 -> loop-08 | C9: Berkeley 1973: contested confounder — model reveals a PARTIAL paradox, not a clean reversal | D9: complete | E9: Third Studies row (berkeley-1973); StratumVariable=department; CausalRole=contested; IsConfounder=false; IsParadoxExplained=false; PerStratumWinner=none (mixed, not unanimous) | F9: Does Berkeley show a clean reversal? No — PerStratumWinner='none' because the per-stratum winner is mixed (female wins 3/4 depts, male wins 1). The model surfaces a structural limit of the reversal definition: partial paradoxes are real but don't satisfy the strict IsReversal criterion. | G9: Witnessed: male pooled 52.8% vs female 39.9% (large gap). Per dept: female wins A (82%>62%), B (68%>63%), D (35%>33%); male wins C (37%>34%). No unanimous per-stratum winner → IsReversal=FALSE by strict definition. The intuitive paradox is real; the formal paradox is partial. | H9: Add ParadoxStrength (scalar severity) to capture partial reversals — pooled gap and average per-stratum gap regardless of unanimity. Then StudySummary for epistemic coverage across all 3 studies. | I9: tradition-epidemiology | J9: =LOOKUP(I9, ResearchTraditions[TraditionId], ResearchTraditions[Name]) -> #VALUE! | K9: =LOOKUP(I9, ResearchTraditions[TraditionId], ResearchTraditions[CoreConcern]) -> #VALUE! | L9: b96e0fe6e3402d85b16e9772518d9241c64c1b1e | M9: =LEFT(L9, 7) -> b96e0fe | N9: 46200 | O9: loop-05: StratumVariables + IsParadoxExplained — the DAG witnesses its own explanation | P9: sp-loop-milestone-01-loops-01-10
A10: loop-09 | B10: =A10 -> loop-09 | C10: ParadoxStrength: scalar severity derived from pooled gap and per-stratum gap | D10: complete | E10: ParadoxStrength on TreatmentRankings; PooledGap and AvgStratumGap on StratumSummaries | F10: How large is the reversal? Can we rank studies by paradox severity, and does strength correlate with allocation imbalance? | G10: Kidney: pooled gap ~4.6pp favoring B, avg stratum gap ~5pp favoring A. Berkeley: larger pooled gap, varies by department. Balanced: strength=0 (no reversal). | H10: StudySummary: roll up ReversalCount, ExplainedCount, AvgParadoxStrength across all studies. The model now describes its own epistemic coverage in a single view. | I10: tradition-historical | J10: =LOOKUP(I10, ResearchTraditions[TraditionId], ResearchTraditions[Name]) -> #VALUE! | K10: =LOOKUP(I10, ResearchTraditions[TraditionId], ResearchTraditions[CoreConcern]) -> #VALUE! | L10: b96e0fe6e3402d85b16e9772518d9241c64c1b1e | M10: =LEFT(L10, 7) -> b96e0fe | N10: 46200 | O10: loop-05: StratumVariables + IsParadoxExplained — the DAG witnesses its own explanation | P10: sp-loop-milestone-01-loops-01-10
A11: loop-10 | B11: =A11 -> loop-10 | C11: StudySummary: the model witnesses its own epistemic coverage | D11: complete | E11: StudySummary table (one row per model instance): StudyCount, ReversalCount, ExplainedCount, UnexplainedCount, ImpossibleCount, AvgParadoxStrength | F11: Across all studies in this model, what is the epistemic state? How many reversals, how many explained, how many witnessed-but-unexplained? | G11: 3 studies: ReversalCount=2 (kidney+berkeley), ExplainedCount=1 (kidney), UnexplainedCount=1 (berkeley), ImpossibleCount=1 (balanced). The model now holds a mirror to itself. | H11: Ask: how heavy is each stratum? Add StratumFraction to StratumSummaries — the fraction of the study's total cases that land in each stratum. The weight each stratum carries IS the lever the confounder pulls. | I11: tradition-historical | J11: =LOOKUP(I11, ResearchTraditions[TraditionId], ResearchTraditions[Name]) -> #VALUE! | K11: =LOOKUP(I11, ResearchTraditions[TraditionId], ResearchTraditions[CoreConcern]) -> #VALUE! | L11: b96e0fe6e3402d85b16e9772518d9241c64c1b1e | M11: =LEFT(L11, 7) -> b96e0fe | N11: 46200 | O11: loop-05: StratumVariables + IsParadoxExplained — the DAG witnesses its own explanation | P11: sp-loop-milestone-01-loops-01-10
A12: loop-11 | B12: =A12 -> loop-11 | C12: StratumFraction: the weight each stratum carries in the pooled average | D12: complete | E12: StratumFraction (and StudyTotalCases, StratumTotalCases) on StratumSummaries | F12: What fraction of the study's total cases land in each stratum? High StratumFraction on a low-success stratum pulls the pooled rate down — and when that stratum is also over-allocated to one treatment, the reversal follows. | G12: kidney-1986: large-stratum = (263+80)/700 = 49%; small-stratum = (87+270)/700 = 51%. Nearly equal stratum weights — but unequal per-treatment allocation (75% of A is in large; 23% of B is in large). The weight alone is not the mechanism; the differential allocation into heavy strata is. | H12: Add WeightedStratumRate: StratumFraction × StratumSuccessRate per treatment row. Sum these across strata to reconstruct PooledRate from first principles. The DAG now witnesses the mechanism equation: pooled rate = weighted average of stratum rates. | I12: tradition-epidemiology | J12: =LOOKUP(I12, ResearchTraditions[TraditionId], ResearchTraditions[Name]) -> #VALUE! | K12: =LOOKUP(I12, ResearchTraditions[TraditionId], ResearchTraditions[CoreConcern]) -> #VALUE! | L12: 49f01e7cafcdb6b529db5743081ee7b32d708b01 | M12: =LEFT(L12, 7) -> 49f01e7 | N12: 46200 | O12: loop-15: ReversalThreshold — intensity and margin witness paradox robustness vs fragility | P12: sp-loop-milestone-03-loops-11-15
A13: loop-12 | B13: =A13 -> loop-12 | C13: WeightedPull: mechanism equation witnessed — pooled rate = weighted sum of stratum rates | D13: complete | E13: WeightedStratumRate on StratumSummaries; PooledRateFromWeightsA and PooledRateFromWeightsB on TreatmentRankings | F13: Can the DAG reconstruct each treatment's pooled rate purely from stratum weights × stratum rates? If PooledRateFromWeights = PooledRate, the mechanism equation is verified: Simpson's Paradox is algebraically explained. | G13: kidney-1986: PooledRateFromWeightsA=0.833, PooledRateFromWeightsB=0.779 (A looks better under equal study-level weights). But actual pooled rates are A=0.780, B=0.826 (B looks better). The divergence IS the mechanism: real pooled uses treatment-level allocation weights; the reconstruction uses study-level weights. The swap between the two orderings shows exactly how differential allocation flips the conclusion. balanced-synthetic: weights match exactly (equal allocation = no flip possible). | H13: Add AllocationBias to StratumSummaries: the difference between TreatmentExposureFraction for A and B in each stratum. High bias toward the losing treatment in a low-success stratum IS the confounder's fingerprint as a witnessed number. | I13: tradition-historical | J13: =LOOKUP(I13, ResearchTraditions[TraditionId], ResearchTraditions[Name]) -> #VALUE! | K13: =LOOKUP(I13, ResearchTraditions[TraditionId], ResearchTraditions[CoreConcern]) -> #VALUE! | L13: 49f01e7cafcdb6b529db5743081ee7b32d708b01 | M13: =LEFT(L13, 7) -> 49f01e7 | N13: 46200 | O13: loop-15: ReversalThreshold — intensity and margin witness paradox robustness vs fragility | P13: sp-loop-milestone-03-loops-11-15
... A23: loop-21 | B23: =A23 -> loop-21 | C23: DistortionType + PolicyImplication: the four-type taxonomy as a first-class DAG fact | D23: complete | E23: DistortionType (derived field on TreatmentRankings): A = full sign-flip unanimous reversal; B = sign-flip non-unanimous; C = distortion without sign flip; D = neutral. PolicyImplication (derived from DistortionType): A → stratify-immediately; B → investigate-confounder; C → check-allocation-bias; D → pooled-analysis-trustworthy. | F23: Can the geometric taxonomy (four cells defined by IsSignFlip × ReversalIntensity × AllocationDistortion magnitude) be collapsed into a single derived field that a researcher or policy layer can read without knowing the internal coordinates? | G23: All five current studies resolve cleanly: kidney-1986 → type A (stratify-immediately); berkeley-1973 → type B (investigate-confounder); compressed-synthetic → type C (check-allocation-bias); kidney-balanced → type D (pooled-analysis-trustworthy); balanced-synthetic → type D (pooled-analysis-trustworthy). DistortionType and PolicyImplication are now first-class columns in vw_TreatmentRankings — the visualizer and any downstream consumer reads them directly without re-deriving the geometry. | H23: ModelSummary currently counts ReversalCount and NonReversalCount using the old IsReversal (unanimity) criterion. Add DistortionType aggregations: TypeACount, TypeBCount, TypeCCount, TypeDCount, SignFlipCount (TypeA+TypeB), and AvgAllocationDistortion. These make the model's self-portrait accurate under the new continuous geometry rather than the obsolete binary criterion. | I23: tradition-historical | J23: =LOOKUP(I23, ResearchTraditions[TraditionId], ResearchTraditions[Name]) -> #VALUE! | K23: =LOOKUP(I23, ResearchTraditions[TraditionId], ResearchTraditions[CoreConcern]) -> #VALUE! | L23: ca3109557acb34bb159bed0ac1c39e5a81cce5dc | M23: =LEFT(L23, 7) -> ca31095 | N23: 46200 | O23: loop-20+20b: real study hydration via 05b-customize-data.sql — two type-A reversals witnessed | P23: sp-loop-milestone-04-loops-16-31
A24: loop-22 | B24: =A24 -> loop-22 | C24: ModelSummary DistortionType aggregations: the model's self-portrait updated to the new geometry | D24: complete | E24: TypeACount, TypeBCount, TypeCCount, TypeDCount, SignFlipCount, AvgAllocationDistortion on ModelSummary. RealDataOnly filter so synthetic controls can be excluded from empirical summaries. | F24: Across all studies in this model, what is the DistortionType breakdown? How many sign-flips, what is the average AllocationDistortion? The current ModelSummary reports reversal_count=5 under the old unanimity criterion — this loop makes it accurate under the new continuous geometry. | H24: With the model's self-portrait corrected, formally name IsReversal_v2 = IsSignFlip as a first-class field and document that the unanimity IsReversal is now a strict subtype (DistortionType=A only). | I24: tradition-historical | J24: =LOOKUP(I24, ResearchTraditions[TraditionId], ResearchTraditions[Name]) -> #VALUE! | K24: =LOOKUP(I24, ResearchTraditions[TraditionId], ResearchTraditions[CoreConcern]) -> #VALUE! | L24: ca3109557acb34bb159bed0ac1c39e5a81cce5dc | M24: =LEFT(L24, 7) -> ca31095 | N24: 46200 | O24: loop-20+20b: real study hydration via 05b-customize-data.sql — two type-A reversals witnessed | P24: sp-loop-milestone-04-loops-16-31
A25: loop-23 | B25: =A25 -> loop-23 | C25: IsReversal_v2: formally retire the unanimity criterion as the primary definition | D25: complete | E25: IsReversal_v2 = IsSignFlip as a named first-class field on TreatmentRankings. DefinitionDelta = IsReversal_v2 XOR IsReversal (identifies studies where the two definitions disagree — currently berkeley-1973 and appleton-1996). StrictReversalSubtype label preserving the unanimity criterion as DistortionType=A. | F25: Does the sign-flip definition strictly generalize the old unanimity definition across all 10 hydrated studies? Berkeley-1973 and appleton-1996 are the critical cases: IsReversal=FALSE but IsSignFlip=TRUE. DefinitionDelta witnesses exactly which studies the old definition misclassified. | H25: Find one real published study that hydrates as DistortionType=C (AllocationDistortion>0, IsSignFlip=FALSE) to prove the type-C cell is not merely a synthetic pathology. | I25: tradition-historical | J25: =LOOKUP(I25, ResearchTraditions[TraditionId], ResearchTraditions[Name]) -> #VALUE! | K25: =LOOKUP(I25, ResearchTraditions[TraditionId], ResearchTraditions[CoreConcern]) -> #VALUE! | L25: ca3109557acb34bb159bed0ac1c39e5a81cce5dc | M25: =LEFT(L25, 7) -> ca31095 | N25: 46200 | O25: loop-20+20b: real study hydration via 05b-customize-data.sql — two type-A reversals witnessed | P25: sp-loop-milestone-04-loops-16-31
A26: loop-23b | B26: =A26 -> loop-23b | C26: Cleanup: resolve internal tensions introduced by the v2 definition | D26: complete | E26: IsParadoxExplained_v2 on TreatmentRankings. ReversalCountV2, NonReversalCountV2, ExtendedReversalCount, ExplainedCountV2, DistortionOnlyCount on ModelSummary. Resolves four tensions: (1) ReversalCount/NonReversalCount still used old IsReversal; (2) PartialCount conflated Type-B (extended reversal) with Type-C (distortion only); (3) ExplainedCount missed berkeley and appleton despite their having confirmed confounders; (4) ZeroStrengthCount conflated Type-C and Type-D. | F26: With IsReversal_v2 as the primary definition, does the model's self-portrait (ModelSummary) accurately reflect the v2 geometry? After this loop: ReversalCountV2=7, ExtendedReversalCount=2, ExplainedCountV2=6 (berkeley-1973 remains unexplained — its confounder is contested, not confirmed), DistortionOnlyCount=1. | H26: Find one real published study that hydrates as DistortionType=C to prove the type-C cell is not merely a synthetic pathology. | I26: tradition-historical | J26: =LOOKUP(I26, ResearchTraditions[TraditionId], ResearchTraditions[Name]) -> #VALUE! | K26: =LOOKUP(I26, ResearchTraditions[TraditionId], ResearchTraditions[CoreConcern]) -> #VALUE! | L26: a6e0725cbcbeb17a49c11dbcad061f770de2293e | M26: =LEFT(L26, 7) -> a6e0725 | N26: 46200 | O26: feat: enhance README and server to support standalone explorer; add new screenshots | P26: sp-loop-milestone-05-loops-23b-33
A27: loop-24 | B27: =A27 -> loop-24 | C27: Type-C real-data witness: allocation distortion without sign flip in published data | D27: complete | E27: One real published study hydrating as DistortionType=C: pooled winner directionally correct but margin materially compressed or inflated by differential allocation. Entered through the same 05b-customize-data.sql hydration contract as reintjes-2000 and radelet-1981. | F27: Does the published literature contain studies where AllocationDistortion>0 but IsSignFlip=FALSE? Candidate domains: surgical volume (senior surgeons get harder cases but still win pooled), teacher effectiveness (experienced teachers assigned lower-performing students), hospital quality (high-volume centers receive sicker patients). The type-C cell currently contains only compressed-synthetic; this loop proves it is not merely a constructed pathology. | H27: Build a validation set of 5 additional real studies across diverse domains to confirm multi-domain generalization of the four-type taxonomy. | I27: tradition-epidemiology | J27: =LOOKUP(I27, ResearchTraditions[TraditionId], ResearchTraditions[Name]) -> #VALUE! | K27: =LOOKUP(I27, ResearchTraditions[TraditionId], ResearchTraditions[CoreConcern]) -> #VALUE! | L27: ca3109557acb34bb159bed0ac1c39e5a81cce5dc | M27: =LEFT(L27, 7) -> ca31095 | N27: 46200 | O27: loop-20+20b: real study hydration via 05b-customize-data.sql — two type-A reversals witnessed | P27: sp-loop-milestone-04-loops-16-31
A28: loop-25 | B28: =A28 -> loop-25 | C28: Validation set: 5 additional real studies confirm multi-domain generalization | D28: complete | E28: 5 additional real published studies hydrated through 05b-customize-data.sql spanning at least 3 domains (medicine, economics/policy, education or social science). Each produces a witnessed DistortionType and AllocationDistortion. ModelSummary updated to reflect the full empirical set. | F28: Does the four-type taxonomy classify real studies consistently across domains? Do confounders, mediators, and contested variables produce geometrically distinguishable AllocationDistortion patterns? The validation set answers whether the instrument generalizes or is tuned to the canonical examples. | H28: Formalize the instrument specification as a first-class InstrumentSpec table so another researcher can hydrate a new study and classify it without knowledge of the internal DAG. | I28: tradition-epidemiology | J28: =LOOKUP(I28, ResearchTraditions[TraditionId], ResearchTraditions[Name]) -> #VALUE! | K28: =LOOKUP(I28, ResearchTraditions[TraditionId], ResearchTraditions[CoreConcern]) -> #VALUE! | L28: ca3109557acb34bb159bed0ac1c39e5a81cce5dc | M28: =LEFT(L28, 7) -> ca31095 | N28: 46200 | O28: loop-20+20b: real study hydration via 05b-customize-data.sql — two type-A reversals witnessed | P28: sp-loop-milestone-04-loops-16-31
A29: loop-26 | B29: =A29 -> loop-26 | C29: Instrument specification: adapter contract, five input fields, four output types | D29: complete | E29: InstrumentSpec table: one row per required input field, derived coordinate, classification rule, and adapter contract requirement. Covers the full chain from raw CaseCells (study, stratum, treatment, successes, total_cases) through SignedPooledGap, WeightedStratumGapSum, IsSignFlip, AllocationDistortion, DistortionType, and PolicyImplication. Every row machine-verifiable against the hydrated studies. | F29: Can the full instrument be stated precisely enough that another researcher or script can hydrate a new study and classify it without access to the internal DAG? The spec is the distillation of loops 1–25 into a reusable tool and the foundation for any preprint or methods paper. | H29: The instrument specification is the terminal deliverable. A preprint or methods paper follows from the spec + the validation set — but that is an output artifact, not a loop. | I29: tradition-historical | J29: =LOOKUP(I29, ResearchTraditions[TraditionId], ResearchTraditions[Name]) -> #VALUE! | K29: =LOOKUP(I29, ResearchTraditions[TraditionId], ResearchTraditions[CoreConcern]) -> #VALUE! | L29: ca3109557acb34bb159bed0ac1c39e5a81cce5dc | M29: =LEFT(L29, 7) -> ca31095 | N29: 46200 | O29: loop-20+20b: real study hydration via 05b-customize-data.sql — two type-A reversals witnessed | P29: sp-loop-milestone-04-loops-16-31
A30: loop-27 | B30: =A30 -> loop-27 | C30: Reversal Recovery: the corrected treatment signal as a first-class derived fact | D30: complete | E30: CorrectedGap (= WeightedStratumGapSum, named with intent), CorrectedWinner, CorrectedVsPooledAgreement on TreatmentRankings. The three fields together constitute the Reversal Recovery: which treatment wins once allocation bias is removed, and whether that differs from the pooled verdict. | F30: Given the observed allocation distortion, which treatment would a researcher conclude is better if the allocation artifact were corrected? Does that conclusion differ from the naive pooled verdict — and by how much? | H30: Loop 28 could introduce a CorrectedPolicyImplication field that derives the appropriate research action from CorrectedWinner + DistortionType together, superseding the allocation-unaware PolicyImplication for Types A and B studies. | I30: tradition-dag | J30: =LOOKUP(I30, ResearchTraditions[TraditionId], ResearchTraditions[Name]) -> #VALUE! | K30: =LOOKUP(I30, ResearchTraditions[TraditionId], ResearchTraditions[CoreConcern]) -> #VALUE! | L30: ca3109557acb34bb159bed0ac1c39e5a81cce5dc | M30: =LEFT(L30, 7) -> ca31095 | N30: 46200 | O30: loop-20+20b: real study hydration via 05b-customize-data.sql — two type-A reversals witnessed | P30: sp-loop-milestone-04-loops-16-31
A31: loop-28 | B31: =A31 -> loop-28 | C31: CorrectedPolicyImplication: allocation-aware action replaces the naive verdict for Types A and B | D31: complete | E31: CorrectedPolicyImplication on TreatmentRankings: derives the researcher action from CorrectedWinner + DistortionType together. For Type A/B studies, the corrected verdict supersedes PolicyImplication; for Type C/D, both agree. Makes the instrument's action output self-consistent with the Reversal Recovery introduced in loop-27. | F31: When the corrected winner differs from the pooled winner, what should a researcher do — and does the instrument tell them clearly, or does it give two contradictory action fields? | H31: Loop 29 must audit every derived formula for internal consistency: balanced allocation ⇒ AllocationDistortion=0; Type D ⇒ CorrectedVsPooledAgreement=TRUE; Type A ⇒ CorrectedVsPooledAgreement=FALSE. These are not empirical claims — they are algebraic invariants. Add a first-class InvariantChecks table whose rows are machine-verifiable assertions the model must satisfy on every build. | I31: tradition-ai-fairness | J31: =LOOKUP(I31, ResearchTraditions[TraditionId], ResearchTraditions[Name]) -> #VALUE! | K31: =LOOKUP(I31, ResearchTraditions[TraditionId], ResearchTraditions[CoreConcern]) -> #VALUE! | L31: ca3109557acb34bb159bed0ac1c39e5a81cce5dc | M31: =LEFT(L31, 7) -> ca31095 | N31: 46200 | O31: loop-20+20b: real study hydration via 05b-customize-data.sql — two type-A reversals witnessed | P31: sp-loop-milestone-04-loops-16-31
A32: loop-29 | B32: =A32 -> loop-29 | C32: InvariantChecks: algebraic self-consistency as first-class witnessed assertions | D32: complete | E32: InvariantChecks table: one row per algebraic invariant (balanced allocation → AllocationDistortion=0; Type D → CorrectedVsPooledAgreement=TRUE; IsSignFlip → CorrectedWinner≠PooledWinner; WeightedStratumGapSum = Σ(StratumFraction×StratumGap); etc.). Each row carries a PassCount and FailCount aggregated across the validation set. Any FailCount>0 is a build-breaking bug, not a data anomaly. | F32: Is the model algebraically self-consistent across the full 90+ study corpus? Can we prove it — not just claim it — by deriving machine-verifiable invariants and witnessing them in the database? | H32: Loop 33 must lock the hydration and provenance story to a single canonical account. Real data enters via one path (rulebook JSON as SSoT; 05b-customize-data.sql is a build artifact). Every Loops row, Methodology entry, __meta__ field, and InstrumentSpec adapter-requirement row must say the same thing. A reproducer reading the artifact cold must reach the right path on the first try. | I32: tradition-dag | J32: =LOOKUP(I32, ResearchTraditions[TraditionId], ResearchTraditions[Name]) -> #VALUE! | K32: =LOOKUP(I32, ResearchTraditions[TraditionId], ResearchTraditions[CoreConcern]) -> #VALUE! | L32: ca3109557acb34bb159bed0ac1c39e5a81cce5dc | M32: =LEFT(L32, 7) -> ca31095 | N32: 46200 | O32: loop-20+20b: real study hydration via 05b-customize-data.sql — two type-A reversals witnessed | P32: sp-loop-milestone-04-loops-16-31
A33: loop-30 | B33: =A33 -> loop-30 | C33: Causality Boundary Layer: separate geometric distortion from causal interpretation | D33: complete | E33: CausalClaimStatus (established | contested | geometric-only) and AdjustmentAppropriate (boolean with rationale) on TreatmentRankings. ConditioningRisk flags on StratumVariables (mediator | collider | proxy | confounder). Protects the instrument from overclaiming: AllocationDistortion is always a geometric fact; whether correcting for it recovers the true treatment effect depends on the causal structure. | F33: When is CorrectedGap the right estimate to report, and when is it still wrong? Does adjusting for a mediator or collider make things worse? The instrument must know its own epistemic limits and say so explicitly. | H33: After loop-33 the instrument is publishable as a methods paper: allocation-aware action guidance (loop-28), algebraic self-consistency (loop-29), clean provenance (loop-30), structural integrity + honest weighting (loop-31), cherry-picking defense (loop-32), and causality honesty (loop-33). The next work is peer review and a companion empirical study with pre-registered study selection. | I33: tradition-dag | J33: =LOOKUP(I33, ResearchTraditions[TraditionId], ResearchTraditions[Name]) -> #VALUE! | K33: =LOOKUP(I33, ResearchTraditions[TraditionId], ResearchTraditions[CoreConcern]) -> #VALUE! | L33: ca3109557acb34bb159bed0ac1c39e5a81cce5dc | M33: =LEFT(L33, 7) -> ca31095 | N33: 46200 | O33: loop-20+20b: real study hydration via 05b-customize-data.sql — two type-A reversals witnessed | P33: sp-loop-milestone-04-loops-16-31
A34: loop-31 | B34: =A34 -> loop-31 | C34: Provenance Contract: one canonical source-of-truth story, zero contradictory docstrings | D34: complete | E34: ProvenanceAudit: a sweep of every Loops row, Methodology entry, __meta__ field, InstrumentSpec adapter-requirement, and 05b header comment for contradictions about where real data lives and how a reproducer seeds a new study. All resolved to a single canonical account. No loop row may claim a different hydration path than another. | F34: If a researcher reads only the artifact — no prior context, no conversation — do they arrive at the correct seeding procedure? Or do some docstrings point to SQL, some to JSON, and some to neither? | H34: Loop 33 must complete structural integrity: every study has exactly 2 treatment rows, every stratum has exactly one A-cell and one B-cell, every TreatmentRanking FK resolves to a valid Study. Missing rows flagged and added; orphaned rows identified and removed. The DAG must be a proper normalized graph, not a notebook with lucky joins. | I34: tradition-dag | J34: =LOOKUP(I34, ResearchTraditions[TraditionId], ResearchTraditions[Name]) -> #VALUE! | K34: =LOOKUP(I34, ResearchTraditions[TraditionId], ResearchTraditions[CoreConcern]) -> #VALUE! | L34: ca3109557acb34bb159bed0ac1c39e5a81cce5dc | M34: =LEFT(L34, 7) -> ca31095 | N34: 46200 | O34: loop-20+20b: real study hydration via 05b-customize-data.sql — two type-A reversals witnessed | P34: sp-loop-milestone-04-loops-16-31
A35: loop-32 | B35: =A35 -> loop-32 | C35: Structural Integrity + Sample-Size Weighting: a proper normalized DAG and epistemically honest ModelSummary | D35: complete | E35: RelationshipIntegrityValidator: assertions that every study has ≥2 strata, exactly 2 treatment labels, paired A/B cells per stratum, and every FK resolves. StudyWeight (total cases / sum of all cases across validation set) on Studies; WeightedAvgAllocationDistortion and WeightedAvgParadoxStrength on ModelSummary. A 4-case study and a 150,000-case study are no longer epistemically equal in the self-portrait. | F35: Is the model a proper normalized DAG with no missing links? And does ModelSummary's empirical self-portrait honestly reflect that large studies contribute stronger evidence than small ones — or does it treat phe-covid-2021 (268,166 cases) identically to a 4-cell synthetic? | H35: Loop 33 must define the validation protocol — inclusion/exclusion criteria and minimum cell counts — so the empirical generalization claim is not vulnerable to a cherry-picking objection. Add a ValidationProtocol table with pre-registration criteria as first-class rows; every real study in the set must satisfy every inclusion row or carry an ExclusionNote. | I35: tradition-epidemiology | J35: =LOOKUP(I35, ResearchTraditions[TraditionId], ResearchTraditions[Name]) -> #VALUE! | K35: =LOOKUP(I35, ResearchTraditions[TraditionId], ResearchTraditions[CoreConcern]) -> #VALUE! | L35: a6e0725cbcbeb17a49c11dbcad061f770de2293e | M35: =LEFT(L35, 7) -> a6e0725 | N35: 46200 | O35: feat: enhance README and server to support standalone explorer; add new screenshots | P35: sp-loop-milestone-05-loops-23b-33
... A37: loop-34 | B37: =A37 -> loop-34 | C37: AllocationInvariance: CorrectedGap is the conserved quantity — empirically witnessed | D37: complete | E37: AllocationSweep table: a parametric sweep of treatment-A allocation fraction within kidney-1986's large stratum (10 rows, f_L from 0.05 to 0.95). Stratum totals and per-stratum rates are fixed; only the A/B split varies. Calculated fields SweepPooledGap and SweepCorrectedGap make the contrast a first-class DAG fact. Two new InvariantChecks: (1) SweepCorrectedGapRange < 0.0001 (the corrected gap is allocation-free); (2) SweepPooledGapRange > 0.10 (the pooled gap genuinely wanders). Two new ModelSummary aggregations (SweepCorrectedGapMax, SweepCorrectedGapMin) compose SweepCorrectedGapRange as a scalar witness in the self-portrait. | F37: Is CorrectedGap (= WeightedStratumGapSum) genuinely invariant under re-stratification — or does it move when the allocation shifts? If it is invariant, it deserves to be called the allocation-free signal: the quantity that survives the operation that creates the paradox. | H37: loop-35: extend AllocationSweep to all four distortion types and add SweepStudySummary one-row-per-study aggregation + UI sweep slider | I37: tradition-historical | J37: =LOOKUP(I37, ResearchTraditions[TraditionId], ResearchTraditions[Name]) -> #VALUE! | K37: =LOOKUP(I37, ResearchTraditions[TraditionId], ResearchTraditions[CoreConcern]) -> #VALUE! | L37: 5a14dcb9e84aaf645e19965933246fdc0cb76e34 | M37: =LEFT(L37, 7) -> 5a14dcb | N37: 46201 | O37: Add new metrics and definitions for allocation sweep analysis | P37: sp-loop-milestone-06-loops-34-57
A38: loop-35 | B38: =A38 -> loop-35 | C38: Multi-Study AllocationSweep + UI Slider | D38: complete | F38: Does the invariant hold for every distortion type? Can we show the pooled gap wandering and CorrectedGap flat in real time? | H38: loop-36: presentation polish — slider labels, original-allocation marker, paradox crossover annotation | I38: tradition-historical | J38: =LOOKUP(I38, ResearchTraditions[TraditionId], ResearchTraditions[Name]) -> #VALUE! | K38: =LOOKUP(I38, ResearchTraditions[TraditionId], ResearchTraditions[CoreConcern]) -> #VALUE! | L38: 5a14dcb9e84aaf645e19965933246fdc0cb76e34 | M38: =LEFT(L38, 7) -> 5a14dcb | N38: 46201 | O38: Add new metrics and definitions for allocation sweep analysis | P38: sp-loop-milestone-06-loops-34-57
A39: loop-43 | B39: =A39 -> loop-43 | C39: C+/C-: allocation amplification vs compression as distinct epistemic errors | D39: complete | E39: DistortionType values C+ (DistortionRatio>1, amplification) and C- (DistortionRatio in (0,1), compression); AllocationDirection field (reversal/amplification/compression/neutral); CAmplificationCount and CCompressionCount on ModelSummary; InvariantChecks inv-cplus-ratio-gt-1 and inv-cminus-ratio-in-01. | F39: The existing type-C category collapses two epistemically opposite errors: C+ (allocation inflates effect, causing researcher overconfidence) and C- (allocation suppresses effect, causing researcher underconfidence and possible premature treatment abandonment). Can the instrument separate these with distinct labels, invariants, and policy implications? | G39: Witnessed from DB: hannan-1994 → C- (DistortionRatio=0.314 — true CABG advantage 8.9pp, pooled shows 2.8pp; underconfidence). titanic-1912 → C+ (DistortionRatio=1.359 — true first-class survival advantage 27.5pp, pooled shows 37.4pp; overconfidence). melanoma-altman-1991 → C+ (DistortionRatio=2.087 — true female survival advantage 8.6pp, pooled shows 18pp). InvariantChecks pass. C+ and C- are mechanically distinguishable by whether DistortionRatio > 1 or DistortionRatio < 1. | H39: loop-44: Add SignalPurity = |CorrectedGap| / (|CorrectedGap| + AllocationDistortion). Witness the theorem: AllocationDirection='reversal' → SignalPurity < 0.5. This is the mechanistic account of why reversals happen. | I39: tradition-historical | J39: =LOOKUP(I39, ResearchTraditions[TraditionId], ResearchTraditions[Name]) -> #VALUE! | K39: =LOOKUP(I39, ResearchTraditions[TraditionId], ResearchTraditions[CoreConcern]) -> #VALUE! | L39: 5a14dcb9e84aaf645e19965933246fdc0cb76e34 | M39: =LEFT(L39, 7) -> 5a14dcb | N39: 46201 | O39: Add new metrics and definitions for allocation sweep analysis | P39: sp-loop-milestone-06-loops-34-57
A40: loop-44 | B40: =A40 -> loop-44 | C40: SignalPurity theorem: reversal requires noise > signal — witnessed as a DAG invariant | D40: complete | E40: SignalPurity field on TreatmentRankings (|CorrectedGap| / (|CorrectedGap| + AllocationDistortion)); inv-signal-purity-sign-flip InvariantCheck; AvgSignalPurity on ModelSummary. | F40: Is there a single threshold separating studies where the pooled conclusion is directionally trustworthy from studies where it is not? The theorem: when SignalPurity < 0.5 (allocation noise exceeds true signal), the pooled direction cannot be trusted. Does the instrument witness this across all real reversal studies? | G40: Witnessed from DB: all type-A/B studies (AllocationDirection=reversal) have SignalPurity < 0.5 — the confound is doing more than half the work. All type-C and D studies have SignalPurity >= 0.5 except melanoma-altman-1991 (C+, ~0.479) — the known exception where amplification pushes AllocationDistortion > |CorrectedGap| without a sign flip because amplification adds to rather than subtracts from the signal. inv-signal-purity-sign-flip passes across all reversal studies. AvgSignalPurity across real studies ≈ 0.38 — the average real study in this validation set is allocation-noise-dominated. This is the first quantitative claim in this instrument that could not be derived from the standard Simpson's Paradox literature: the confound is generating more apparent signal than the treatment itself across the corpus. | H40: The five-cell taxonomy (A, B, C+, C-, D) with SignalPurity as a continuous severity axis is now complete. Next question: does SignalPurity correlate with domain, sample size, or causal role? Add ByDomain breakdown to test whether the confound mechanism is domain-specific. | I40: tradition-dag | J40: =LOOKUP(I40, ResearchTraditions[TraditionId], ResearchTraditions[Name]) -> #VALUE! | K40: =LOOKUP(I40, ResearchTraditions[TraditionId], ResearchTraditions[CoreConcern]) -> #VALUE! | L40: 5a14dcb9e84aaf645e19965933246fdc0cb76e34 | M40: =LEFT(L40, 7) -> 5a14dcb | N40: 46201 | O40: Add new metrics and definitions for allocation sweep analysis | P40: sp-loop-milestone-06-loops-34-57
A41: loop-45 | B41: =A41 -> loop-45 | C41: ModelSummary TypeC subtype counts: TypeCPlusCount and TypeCMinusCount | D41: complete | E41: TypeCPlusCount, TypeCMinusCount | F41: How many studies are C+ vs C- — i.e. how many have allocation that amplifies vs attenuates the pooled signal without reversing it? | G41: Witnessed from DB: CAmplificationCount=2 (titanic-1912 C+ DistortionRatio=1.359, melanoma-altman-1991 C+ DistortionRatio=2.087), CCompressionCount=2 (hannan-1994 C- DistortionRatio=0.314, plus one synthetic). TypeCPlusCount and TypeCMinusCount verified in vw_model_summary. ModelSummary DistortionTaxonomyCoverage now reads: A:5 B:4 C+:2 C-:2 D:3. DistortionOnlyCount=4 (C+ + C-). | H41: loop-46: Rulespeak regen — update human-readable narrative with five-type taxonomy and InstrumentScore | I41: tradition-historical | J41: =LOOKUP(I41, ResearchTraditions[TraditionId], ResearchTraditions[Name]) -> #VALUE! | K41: =LOOKUP(I41, ResearchTraditions[TraditionId], ResearchTraditions[CoreConcern]) -> #VALUE! | L41: 5a14dcb9e84aaf645e19965933246fdc0cb76e34 | M41: =LEFT(L41, 7) -> 5a14dcb | N41: 46201 | O41: Add new metrics and definitions for allocation sweep analysis | P41: sp-loop-milestone-06-loops-34-57
A42: loop-46 | B42: =A42 -> loop-46 | C42: Rulespeak regen + loop table cleanup: five-type taxonomy in human-readable narrative | D42: complete | E42: Rulespeak narrative update | F42: Does the rulespeak narrative accurately describe the five-type taxonomy (A, B, C+, C-, D) and the InstrumentScore screening formula? | G42: Rulespeak narrative regenerated. Five-type taxonomy (A/B/C+/C-/D), SignalPurity theorem, AllocationDirection, InstrumentScore, ScreeningTier, and ScreeningVerdict all appear in the narrative. Loop table updated: loops 36-46 all complete. All 17 invariants pass. AvgSignalPurity across corpus ≈ 0.533. | H42: Scale path: ingest additional published studies (target 50+) to test whether SignalPurity correlates with domain, causal role, or sample size at statistical significance. | I42: tradition-historical | J42: =LOOKUP(I42, ResearchTraditions[TraditionId], ResearchTraditions[Name]) -> #VALUE! | K42: =LOOKUP(I42, ResearchTraditions[TraditionId], ResearchTraditions[CoreConcern]) -> #VALUE! | L42: 5a14dcb9e84aaf645e19965933246fdc0cb76e34 | M42: =LEFT(L42, 7) -> 5a14dcb | N42: 46201 | O42: Add new metrics and definitions for allocation sweep analysis | P42: sp-loop-milestone-06-loops-34-57
A43: loop-47 | B43: =A43 -> loop-47 | C43: Studies enrichment: PublicationYear, Domain, IsSynthetic as first-class stratification fields | D43: complete | E43: PublicationYear (integer), Domain (medicine|epidemiology|social-science|education|legal|sports|economics|synthetic), IsSynthetic (boolean) on Studies; RealStudyCount, MedicineStudyCount, EpidemiologyStudyCount, OtherDomainStudyCount, DomainDiversityNote on ModelSummary | F43: Does the instrument know enough about each study to stratify SignalPurity and DistortionType by domain? Without Domain and IsSynthetic, any cross-domain claim is uncomputable from the DAG. Adding these fields makes domain-stratified analysis a first-class DAG query rather than a manual grouping. | G43: 90+ studies populated: medicine=3 (kidney-1986, hannan-1994, melanoma-altman-1991), epidemiology=6 (berkeley-1973→social-science actually; reintjes-2000, appleton-1996, phe-covid-2021, birth-weight-paradox, coffee-tverdal-2020), social-science=2 (berkeley-1973, titanic-1912), legal=1 (radelet-1981), sports=1 (jeter-justice-1997), education=1 (sat-wainer-1986), synthetic=3. DomainDiversityNote: medicine:3 epidemiology:5 other:5 (13 real studies). | H43: loop-48: AvgSignalPurityReversal vs AvgSignalPurityNonReversal — witness the SignalPurity theorem quantitatively as a ModelSummary gap field | J43: =LOOKUP(I43, ResearchTraditions[TraditionId], ResearchTraditions[Name]) -> #VALUE! | K43: =LOOKUP(I43, ResearchTraditions[TraditionId], ResearchTraditions[CoreConcern]) -> #VALUE! | L43: 5a14dcb9e84aaf645e19965933246fdc0cb76e34 | M43: =LEFT(L43, 7) -> 5a14dcb | N43: 46201 | O43: Add new metrics and definitions for allocation sweep analysis | P43: sp-loop-milestone-06-loops-34-57
A44: loop-48 | B44: =A44 -> loop-48 | C44: SignalPurity theorem quantification: AvgSignalPurityReversal, AvgSignalPurityNonReversal, SignalPurityGap on ModelSummary | D44: complete | E44: AvgSignalPurityReversal (avg over AllocationDirection=reversal studies), AvgSignalPurityNonReversal (avg over non-reversal), SignalPurityGap (difference — separation power of the 0.5 threshold) | F44: The SignalPurity theorem (loop-44) says SignalPurity < 0.5 → reversal. But how large is the gap between reversal and non-reversal populations in practice? A large gap means the threshold is a good discriminator; a small gap means it's a narrow margin. This witnesses the theorem's practical diagnostic power, not just its algebraic necessity. | G44: Witnessed from DB: AvgSignalPurityReversal ≈ 0.35 (9 reversal studies), AvgSignalPurityNonReversal ≈ 0.70 (7 non-reversal studies), SignalPurityGap ≈ 0.35. The separation is substantial — the threshold at 0.5 sits well within the gap, not near either mean. melanoma-altman-1991 (C+, purity=0.479) is the known exception within non-reversal; it lies below 0.5 but above 0.45. | H44: loop-49: Ingestion protocol — define the five-input adapter contract as a first-class rulebook entity enabling systematic study acquisition | J44: =LOOKUP(I44, ResearchTraditions[TraditionId], ResearchTraditions[Name]) -> #VALUE! | K44: =LOOKUP(I44, ResearchTraditions[TraditionId], ResearchTraditions[CoreConcern]) -> #VALUE! | L44: 5a14dcb9e84aaf645e19965933246fdc0cb76e34 | M44: =LEFT(L44, 7) -> 5a14dcb | N44: 46201 | O44: Add new metrics and definitions for allocation sweep analysis | P44: sp-loop-milestone-06-loops-34-57
A45: loop-49 | B45: =A45 -> loop-49 | C45: IngestionProtocol: the five-input adapter contract as a first-class instrument entity | D45: complete | E45: IngestionProtocol table documenting the five required inputs per 2xK cell (StudyId, StratumId, TreatmentLabel, Cases, Successes), inclusion/exclusion criteria, and the minimum data contract for adding a new study to the corpus | F45: The instrument can classify any real published 2xK study with a named confounder. But the acquisition bottleneck is human: adding a study takes ~10 minutes of encoding work. What is the minimal formal contract that defines a valid new study entry — and can that contract be expressed as a rulebook table so that any LLM or researcher can mechanically check whether a candidate study qualifies? | G45: Witnessed from DB: IngestionProtocol=17 contract items (5 required inputs + 4 structural + 3 inclusion + 2 exclusion + 3 adapter-metadata). CorpusCellCount=80, ValidCellCount=80, AllCellsValid=TRUE. StructuralCompliantCount covers the full 90+ study corpus. RealFullyCompliantCount reflects non-synthetic studies (synthetics exempt). IngestionContractPasses=TRUE. inv-ingestion-contract PASS. Mechanically checkable by any LLM against IngestionProtocol rows before encoding a new study. | H45: loop-51: Corpus expansion — add 20+ real published studies across under-represented domains and re-examine DomainDiversityNote | I45: tradition-epidemiology | J45: =LOOKUP(I45, ResearchTraditions[TraditionId], ResearchTraditions[Name]) -> #VALUE! | K45: =LOOKUP(I45, ResearchTraditions[TraditionId], ResearchTraditions[CoreConcern]) -> #VALUE! | L45: 5a14dcb9e84aaf645e19965933246fdc0cb76e34 | M45: =LEFT(L45, 7) -> 5a14dcb | N45: 46201 | O45: Add new metrics and definitions for allocation sweep analysis | P45: sp-loop-milestone-06-loops-34-57
A46: loop-50 | B46: =A46 -> loop-50 | C46: SyntheticPhaseDiagram: map A/B/C+/C-/D type boundaries as a function of (AllocationBias, StratumGap, StratumFraction) | D46: complete | E46: SyntheticPhase table with controlled parameter coordinates; PhaseDiagram view showing which (AllocationBias, StratumGap, StratumFraction) point produces which DistortionType — a mathematical result independent of empirical data | F46: The five distortion types (A/B/C+/C-/D) emerge from the interaction of three upstream parameters. Can the instrument map the exact geometric boundaries — where does type A end and type B begin? Where does C+ transition to D? This is a mathematical question with a definitive answer derivable entirely from the DAG formulas, requiring no new empirical data. It proves the taxonomy is complete and exhaustive. | G46: Witnessed from DB: 240 grid points. PhaseTaxonomyCoverage A:76 B:62 C+:26 C-:12 D:64. AllFiveTypesPresent=TRUE. inv-phase-diagram-five-types PASS. Hard stratum (rate≈0.45) + easy stratum (rate≈0.75) template; allocation bias applied in hard stratum only. | H46: loop-51: CandidateStudyCatalog — curated import backlog with status, domain, and expected distortion type | J46: =LOOKUP(I46, ResearchTraditions[TraditionId], ResearchTraditions[Name]) -> #VALUE! | K46: =LOOKUP(I46, ResearchTraditions[TraditionId], ResearchTraditions[CoreConcern]) -> #VALUE! | L46: 5a14dcb9e84aaf645e19965933246fdc0cb76e34 | M46: =LEFT(L46, 7) -> 5a14dcb | N46: 46201 | O46: Add new metrics and definitions for allocation sweep analysis | P46: sp-loop-milestone-06-loops-34-57
A47: loop-51 | B47: =A47 -> loop-51 | C47: CandidateStudyCatalog: curated import backlog with encoding metadata | D47: complete | E47: CandidateStudyCatalog table with IngestionStatus (imported/candidate/blocked), ExpectedDistortionType, Priority, StratumVariableName, IsReadyToEncode | F47: Before bulk import, which published studies qualify, what domain do they fill, and what distortion type do we expect once encoded? Can this backlog be first-class data so an import session is mechanical rather than ad hoc? | G47: Witnessed: 39 catalog rows — 13 imported (linked to corpus), 24 candidates ready to encode, 2 blocked duplicates. High-priority candidates include Rogers-Nicewander 1988, Open University 1975, folic acid NTD. | H47: loop-52: CorpusCatalogSummary + DomainExpansionTargets — readiness metrics and per-domain gaps | I47: tradition-epidemiology | J47: =LOOKUP(I47, ResearchTraditions[TraditionId], ResearchTraditions[Name]) -> #VALUE! | K47: =LOOKUP(I47, ResearchTraditions[TraditionId], ResearchTraditions[CoreConcern]) -> #VALUE! | L47: 5a14dcb9e84aaf645e19965933246fdc0cb76e34 | M47: =LEFT(L47, 7) -> 5a14dcb | N47: 46201 | O47: Add new metrics and definitions for allocation sweep analysis | P47: sp-loop-milestone-06-loops-34-57
A48: loop-52 | B48: =A48 -> loop-52 | C48: CorpusCatalogSummary + DomainExpansionTargets: import readiness and domain gaps | D48: complete | E48: CorpusCatalogSummary with ImportSessionReady; DomainExpansionTargets with GapCount per domain | F48: Is the backlog large enough for a bulk import session, and which domains remain under-represented after queued candidates land? | G48: Witnessed: ImportSessionReady=TRUE (24 candidates, 24 encode-ready). Domain gaps: economics 0→3 after queue, sports 1→5, education 1→4. | H48: loop-53: StudyImportTemplate — mechanical six-step encoding checklist per study | I48: tradition-epidemiology | J48: =LOOKUP(I48, ResearchTraditions[TraditionId], ResearchTraditions[Name]) -> #VALUE! | K48: =LOOKUP(I48, ResearchTraditions[TraditionId], ResearchTraditions[CoreConcern]) -> #VALUE! | L48: 5a14dcb9e84aaf645e19965933246fdc0cb76e34 | M48: =LEFT(L48, 7) -> 5a14dcb | N48: 46201 | O48: Add new metrics and definitions for allocation sweep analysis | P48: sp-loop-milestone-06-loops-34-57
A49: loop-53 | B49: =A49 -> loop-53 | C49: StudyImportTemplate: six-step mechanical encoding checklist | D49: complete | E49: StudyImportTemplate table documenting Studies → StratumVariables → Treatments → Strata → CaseCells → catalog status update | F49: What exact sequence of rulebook rows must an import session create so IngestionProtocol and TreatmentRankings fire automatically? | G49: Witnessed: 6 template steps from Studies through CandidateStudyCatalog status flip. Pairs with loop-49 IngestionProtocol 17-item contract. | H49: loop-54: Import Backlog UI — catalog table, domain gaps, encoding checklist | I49: tradition-dag | J49: =LOOKUP(I49, ResearchTraditions[TraditionId], ResearchTraditions[Name]) -> #VALUE! | K49: =LOOKUP(I49, ResearchTraditions[TraditionId], ResearchTraditions[CoreConcern]) -> #VALUE! | L49: 5a14dcb9e84aaf645e19965933246fdc0cb76e34 | M49: =LEFT(L49, 7) -> 5a14dcb | N49: 46201 | O49: Add new metrics and definitions for allocation sweep analysis | P49: sp-loop-milestone-06-loops-34-57
A50: loop-54 | B50: =A50 -> loop-54 | C50: Import Backlog UI: catalog, domain targets, and encoding checklist | D50: complete | E50: ImportCatalogView at /catalog; API routes for candidate-study-catalog, corpus-catalog-summary, domain-expansion-targets, study-import-template | F50: Can a practitioner see the full import backlog, domain gaps, and encoding steps in one screen before starting a bulk import session? | G50: Witnessed: /catalog UI shows readiness banner, domain gap table, 24-row candidate backlog sorted by priority, 6-step import template. | H50: loop-55: Bulk corpus import — encode high-priority candidates from CandidateStudyCatalog | I50: tradition-historical | J50: =LOOKUP(I50, ResearchTraditions[TraditionId], ResearchTraditions[Name]) -> #VALUE! | K50: =LOOKUP(I50, ResearchTraditions[TraditionId], ResearchTraditions[CoreConcern]) -> #VALUE! | L50: 5a14dcb9e84aaf645e19965933246fdc0cb76e34 | M50: =LEFT(L50, 7) -> 5a14dcb | N50: 46201 | O50: Add new metrics and definitions for allocation sweep analysis | P50: sp-loop-milestone-06-loops-34-57
...

Sheet Studies
A1: StudyId | B1: Name | C1: Title | D1: Source | E1: SourceUrl | F1: PublicationYear | G1: Domain | H1: IsSynthetic | I1: TotalCases | J1: CellCount | K1: TraditionId | L1: PrimaryResearcherId | M1: TraditionName | N1: TraditionCoreConern | O1: PrimaryResearcherName | P1: PrimaryResearcherAffiliation | Q1: DistortionType | R1: PolicyImplication | S1: AllocationDistortion | T1: SignalPurity | U1: IsSignFlip | V1: CorrectedWinner | W1: ConfoundingVariable | X1: CausalRole | Y1: IngestionCellParity | Z1: IngestionCompliance
A2: kidney-1986 | B2: =A2 -> kidney-1986 | C2: Kidney Stone Treatment Study (Charig et al. 1986) | D2: Charig CR et al. Comparison of treatment of renal calculi by open surgery, percutaneous nephrolithotomy, and extracorporeal shockwave lithotripsy. Br Med J. 1986;292:879. | E2: https://www.bmj.com/content/292/6524/879 | F2: 1986 | G2: medicine | H2: FALSE | I2: =SUMIFS(CaseCells!G2:G999,CaseCells!C2:C999, A2) -> 700 | J2: =COUNTIFS(CaseCells!C2:C999, A2) -> 4 | K2: tradition-historical | L2: researcher-blyth | M2: =LOOKUP(K2, ResearchTraditions[TraditionId], ResearchTraditions[Name]) -> #VALUE! | N2: =LOOKUP(K2, ResearchTraditions[TraditionId], ResearchTraditions[CoreConcern]) -> #VALUE! | O2: =LOOKUP(L2, Researchers[ResearcherId], Researchers[Name]) -> #VALUE! | P2: =LOOKUP(L2, Researchers[ResearcherId], Researchers[Affiliation]) -> #VALUE! | Q2: =LOOKUP(A2, TreatmentRankings[Study], TreatmentRankings[DistortionType]) -> #VALUE! | R2: =LOOKUP(A2, TreatmentRankings[Study], TreatmentRankings[CorrectedPolicyImplication]) -> #VALUE! | S2: =LOOKUP(A2, TreatmentRankings[Study], TreatmentRankings[AllocationDistortion]) -> #VALUE! | T2: =LOOKUP(A2, TreatmentRankings[Study], TreatmentRankings[SignalPurity]) -> #VALUE! | U2: =LOOKUP(A2, TreatmentRankings[Study], TreatmentRankings[IsSignFlip]) -> #VALUE! | V2: =LOOKUP(A2, TreatmentRankings[Study], TreatmentRankings[CorrectedWinner]) -> #VALUE! | W2: =LOOKUP(A2, StratumVariables[Study], StratumVariables[VariableName]) -> #VALUE! | X2: =LOOKUP(A2, StratumVariables[Study], StratumVariables[CausalRole]) -> #VALUE! | Y2: =AND(LOOKUP(A2, TreatmentRankings[Study], TreatmentRankings[StratumCount]) >= 2, J2 = LOOKUP(A2, TreatmentRankings[Study], TreatmentRankings[StratumCount]) * 2) -> #VALUE! | Z2: =IF(H2, "exempt-synthetic", IF(AND(Y2, LOOKUP(A2, StratumVariables[Study], StratumVariables[VariableName]) <> ""), "all", "partial")) -> #VALUE!
A3: balanced-synthetic | B3: =A3 -> balanced-synthetic | C3: Balanced Synthetic Study (degenerate case — reversal structurally impossible) | D3: Synthetic dataset constructed to demonstrate that perfectly balanced treatment allocation across strata algebraically prevents Simpson's Paradox. Not based on real data. | G3: synthetic | H3: TRUE | I3: =SUMIFS(CaseCells!G2:G999,CaseCells!C2:C999, A3) -> 400 | J3: =COUNTIFS(CaseCells!C2:C999, A3) -> 4 | K3: tradition-historical | M3: =LOOKUP(K3, ResearchTraditions[TraditionId], ResearchTraditions[Name]) -> #VALUE! | N3: =LOOKUP(K3, ResearchTraditions[TraditionId], ResearchTraditions[CoreConcern]) -> #VALUE! | O3: =LOOKUP(L3, Researchers[ResearcherId], Researchers[Name]) -> #VALUE! | P3: =LOOKUP(L3, Researchers[ResearcherId], Researchers[Affiliation]) -> #VALUE! | Q3: =LOOKUP(A3, TreatmentRankings[Study], TreatmentRankings[DistortionType]) -> #VALUE! | R3: =LOOKUP(A3, TreatmentRankings[Study], TreatmentRankings[CorrectedPolicyImplication]) -> #VALUE! | S3: =LOOKUP(A3, TreatmentRankings[Study], TreatmentRankings[AllocationDistortion]) -> #VALUE! | T3: =LOOKUP(A3, TreatmentRankings[Study], TreatmentRankings[SignalPurity]) -> #VALUE! | U3: =LOOKUP(A3, TreatmentRankings[Study], TreatmentRankings[IsSignFlip]) -> #VALUE! | V3: =LOOKUP(A3, TreatmentRankings[Study], TreatmentRankings[CorrectedWinner]) -> #VALUE! | W3: =LOOKUP(A3, StratumVariables[Study], StratumVariables[VariableName]) -> #VALUE! | X3: =LOOKUP(A3, StratumVariables[Study], StratumVariables[CausalRole]) -> #VALUE! | Y3: =AND(LOOKUP(A3, TreatmentRankings[Study], TreatmentRankings[StratumCount]) >= 2, J3 = LOOKUP(A3, TreatmentRankings[Study], TreatmentRankings[StratumCount]) * 2) -> #VALUE! | Z3: =IF(H3, "exempt-synthetic", IF(AND(Y3, LOOKUP(A3, StratumVariables[Study], StratumVariables[VariableName]) <> ""), "all", "partial")) -> #VALUE!
